<?xml version="1.0" encoding="utf-8"?>
<!-- This URDF was automatically created by SolidWorks to URDF Exporter! Originally created by Stephen Brawner (brawner@gmail.com) 
     Commit Version: 1.6.0-4-g7f85cfe  Build Version: 1.6.7995.38578
     For more information, please see http://wiki.ros.org/sw_urdf_exporter -->
<robot name="urdf_file">
  <link name="base_link">
    <inertial>
      <origin
        xyz="-0.108085 -3.4694E-18 0.5"
        rpy="0 0 0" />
      <mass
        value="0.0010091" />
      <inertia
        ixx="1.4934E-08"
        ixy="-1.0785E-24"
        ixz="-1.0572E-09"
        iyy="6.7127E-08"
        iyz="-6.4523E-25"
        izz="8.0345E-08" />
    </inertial>
    <visual>
      <origin
        xyz="0 0 0"
        rpy="0 0 0" />
      <geometry>
        <mesh
          filename="package://serial_4bar/meshes/base_link.STL" />
      </geometry>
      <material
        name="">
        <color
          rgba="0.1 0.1 0.53 1" />
      </material>
    </visual>
    <collision>
      <origin
        xyz="0 0 0"
        rpy="0 0 0" />
      <geometry>
        <box size = "0.01357 0.02 0.002"/>
      </geometry>
    </collision>
  </link>

  <link
  name="link2">
    <inertial>
      <origin
        xyz="0.0097543 0.0096735 -0.0011662"
        rpy="0 0 0" />
      <mass
        value="0.0012602" />
      <inertia
        ixx="7.9092E-08"
        ixy="-6.031E-08"
        ixz="-1.0828E-09"
        iyy="8.0095E-08"
        iyz="-1.0738E-09"
        izz="1.5719E-07" />
    </inertial>
    <visual>
      <origin
        xyz="0 0 0"
        rpy="0 0 0" />
      <geometry>
        <mesh
          filename="package://serial_4bar/meshes/link2.STL" />
      </geometry>
      <material
        name="">
        <color
          rgba="0.79216 0.81961 0.93333 1" />
      </material>
    </visual>
    <collision>
      <origin
        xyz="0 0 0"
        rpy="0 0 0" />
      <geometry>
        <box size = "0.01357 0.02 0.002"/>
      </geometry>
    </collision>
  </link>
  <joint
    name="joint1"
    type="revolute">
    <origin
      xyz="0 0 0"
      rpy="0 0 0" />
    <parent
      link="base_link" />
    <child
      link="link2" />
    <axis
      xyz="0 0 1" />
  </joint>
  <link
    name="link3">
    <inertial>
      <origin
        xyz="0.013381 -0.0031119 -0.0013738"
        rpy="0 0 0" />
      <mass
        value="0.0012602" />
      <inertia
        ixx="2.5471E-08"
        ixy="2.6614E-08"
        ixz="1.4854E-09"
        iyy="1.3372E-07"
        iyz="-3.4545E-10"
        izz="1.5719E-07" />
    </inertial>
    <visual>
      <origin
        xyz="0 0 0"
        rpy="0 0 0" />
      <geometry>
        <mesh
          filename="package://serial_4bar/meshes/link3.STL" />
      </geometry>
      <material
        name="">
        <color
          rgba="0.79216 0.81961 0.93333 1" />
      </material>
    </visual>
    <collision>
      <origin
        xyz="0 0 0"
        rpy="0 0 0" />
      <geometry>
        <box size = "0.01357 0.02 0.002"/>
      </geometry>
    </collision>
  </link>
  <joint
    name="joint2"
    type="continuous">
    <origin
      xyz="0.018035 0.017886 0.00254"
      rpy="0 0 0.78124" />
    <parent
      link="link2" />
    <child
      link="link3" />
    <axis
      xyz="0 0 1" />
  </joint>
  <link
    name="link4">
    <inertial>
      <origin
        xyz="0.0078003 -0.0033992 0.00127"
        rpy="0 0 0" />
      <mass
        value="0.00093174" />
      <inertia
        ixx="2.4284E-08"
        ixy="1.1097E-08"
        ixz="-1.7097E-25"
        iyy="4.4912E-08"
        iyz="9.198E-26"
        izz="6.8193E-08" />
    </inertial>
    <visual>
      <origin
        xyz="0 0 0"
        rpy="0 0 0" />
      <geometry>
        <mesh
          filename="package://serial_4bar/meshes/link4.STL" />
      </geometry>
      <material
        name="">
        <color
          rgba="0.79216 0.81961 0.93333 1" />
      </material>
    </visual>
    <collision>
      <origin
        xyz="0 0 0"
        rpy="0 0 0" />
      <geometry>
        <box size = "0.01 0.01357 0.002"/>
      </geometry>
    </collision>
  </link>
  <joint
    name="joint3"
    type="continuous">
    <origin
      xyz="0.02474 -0.0057537 -0.00508"
      rpy="0 0 -0.22851" />
    <parent
      link="link3" />
    <child
      link="link4" />
    <axis
      xyz="0 0 1" />
  </joint>
</robot>